
sqlalchemy.exc.StatementError: (exceptions.UnicodeDecodeError) 'utf8' codec can't decode byte 0xdd in position 12: invalid continuation byte [SQL: u'INSERT INTO ins00 (data) VALUES (%(data)s) RETURNING ins00.id']

++++++++++++++++++++++++++++++++++++++++++++++++++++++++++++++++++++++++++++++++++++++++++++++++++++++++



21
down vote
accepted
I have solved the issue. The title column was being returned by SQLAlchemy as a str and not Unicode. I thought adding encoding='utf8' as an argument to create_engine would take care of this, however, the right way to do it is to pass it in the database URI: mysql://me@myserver/mydatabase?charset=utf8 .

Thank you for all your answers!

++++++++++++++++++++++++++++++++++++++++++++++++++++++++++++++++++++++++

cp1255

++++++++++++++++++++++++++++++++++++++++++++++++++++++++++++++++++++++++

str = unicode(str, errors='replace')
or

str = unicode(str, errors='ignore')

++++++++++++++++++++++++++++++++++++++++++++++++++++++++++++++++++++++++












[2017-02-07 16:33:26,523: INFO/Worker-1] ..db looking up with query: SELECT id, data FROM ins00 WHERE LOWER(data->>'lname') LIKE LOWER('%Martinez%') AND LOWER(data->>'fname') LIKE LOWER('%Erick%') 

[2017-02-07 16:33:26,533: INFO/MainProcess] Task ins00.flex_find_data[0f4f50be-8df2-48b9-8c6a-7efd8b5a2b2d] succeeded in 0.0591604819056s: 'The following keys are allowed in search: lname,acctnum,cust_id,hid,fname<br>\n<br>\n'
[2017-02-07 16:33:39,217: INFO/MainProcess] Received task: ins00.flex_find_data[3f71f90d-34ad-4fa4-9ae1-bf061772fd1d]
[2017-02-07 16:33:54,462: INFO/MainProcess] Received task: ins00.flex_find_data[aa4e30a8-598d-448d-98b3-6d742a975630]
Traceback (most recent call last):
  File "readers/ins00_reader_245.py", line 50, in <module>
    meta.tables['ins00'].insert().values(data=row)
  File "/usr/local/lib/python2.7/dist-packages/sqlalchemy/engine/base.py", line 2055, in execute
    return connection.execute(statement, *multiparams, **params)
  File "/usr/local/lib/python2.7/dist-packages/sqlalchemy/engine/base.py", line 945, in execute
    return meth(self, multiparams, params)
  File "/usr/local/lib/python2.7/dist-packages/sqlalchemy/sql/elements.py", line 263, in _execute_on_connection
    return connection._execute_clauseelement(self, multiparams, params)
  File "/usr/local/lib/python2.7/dist-packages/sqlalchemy/engine/base.py", line 1053, in _execute_clauseelement
    compiled_sql, distilled_params
  File "/usr/local/lib/python2.7/dist-packages/sqlalchemy/engine/base.py", line 1121, in _execute_context
    None, None)
  File "/usr/local/lib/python2.7/dist-packages/sqlalchemy/engine/base.py", line 1393, in _handle_dbapi_exception
    exc_info
  File "/usr/local/lib/python2.7/dist-packages/sqlalchemy/util/compat.py", line 203, in raise_from_cause
    reraise(type(exception), exception, tb=exc_tb, cause=cause)
  File "/usr/local/lib/python2.7/dist-packages/sqlalchemy/engine/base.py", line 1116, in _execute_context
    context = constructor(dialect, self, conn, *args)
  File "/usr/local/lib/python2.7/dist-packages/sqlalchemy/engine/default.py", line 639, in _init_compiled
    for key in compiled_params
  File "/usr/local/lib/python2.7/dist-packages/sqlalchemy/engine/default.py", line 639, in <genexpr>
    for key in compiled_params
  File "/usr/local/lib/python2.7/dist-packages/sqlalchemy/sql/sqltypes.py", line 1977, in process
    serialized = json_serializer(value)
  File "/usr/lib/python2.7/json/__init__.py", line 243, in dumps
    return _default_encoder.encode(obj)
  File "/usr/lib/python2.7/json/encoder.py", line 207, in encode
    chunks = self.iterencode(o, _one_shot=True)
  File "/usr/lib/python2.7/json/encoder.py", line 270, in iterencode
    return _iterencode(o, 0)
sqlalchemy.exc.StatementError: (exceptions.UnicodeDecodeError) 'utf8' codec can't decode byte 0xdd in position 12: invalid continuation byte [SQL: u'INSERT INTO ins00 (data) VALUES (%(data)s) RETURNING ins00.id']
[2017-02-07 16:41:37,647: INFO/MainProcess] Task ins00.load_ins00_data[03bf4355-b04c-48ba-9448-da939fa609fc] succeeded in 571.044262017s: 'data = Med_245_tall.txt<br>\nreader = ins00_reader_245.py<br>\n1'
[2017-02-07 16:41:37,665: INFO/Worker-1] ..db looking up with query: SELECT id, data FROM ins00 WHERE LOWER(data->>'lname') LIKE LOWER('%Martinez%') AND LOWER(data->>'fname') LIKE LOWER('%Erick%') 
[2017-02-07 16:41:37,669: INFO/MainProcess] Task ins00.flex_find_data[aa4e30a8-598d-448d-98b3-6d742a975630] succeeded in 0.0196228779387s: 'The following keys are allowed in search: lname,acctnum,cust_id,hid,fname<br>\n<br>\n'
[2017-02-07 16:41:37,696: INFO/Worker-2] ..db looking up with query: SELECT id, data FROM ins00 WHERE LOWER(data->>'fname') LIKE LOWER('%Erick%') 
[2017-02-07 16:41:37,700: INFO/MainProcess] Task ins00.flex_find_data[3f71f90d-34ad-4fa4-9ae1-bf061772fd1d] succeeded in 0.0531118488871s: 'The following keys are allowed in search: lname,acctnum,cust_id,hid,fname<br>\n<br>\n'
